Workbook

Sheet Epics
A1: Epic Key | B1: Epic Name | C1: Description | D1: Primary Code Location
A2: MG-E1 | B2: MarketsGrid Public Component & Toolbar Chrome | C2: Top-level <MarketsGrid> React widget — props, imperative handle, primary toolbar with editable caption, save flash, settings/admin buttons, info popover. | D2: packages/react/widgets/markets-grid/src/MarketsGrid.tsx
A3: MG-E2 | B3: AG-Grid Enterprise Integration | C3: Sorting, filtering, grouping, pivoting, pagination, side bar, status bar, frozen rows/columns, virtual scrolling, copy/paste, Excel export — surfaced through MarketsGrid props. | D3: packages/react/widgets/markets-grid (AgGridReact wrapper)
A4: MG-E3 | B4: Streaming Data Performance | C4: Optimizations for live-updating data: 100ms transaction batching, focus-stable filter inputs, surgical repaints on conditional styling. | D4: packages/react/widgets/markets-grid + grid-react/src/modules
A5: MG-E4 | B5: Grid Platform & Module System (Core) | C5: Vanilla-TS GridPlatform: EventBus, ApiHub, ResourceScope, CssInjector, PipelineRunner, topo-sorted module activation, dirty bus. | D5: packages/shared/core/src/platform/*
A6: MG-E5 | B6: Layout / Profile Management | C6: Layouts as named saved combos of everything. ProfileManager state machine, switch dialog, clone naming, JSON export/import, browser unload warning. | D6: packages/shared/core/src/profiles, ProfileSelector.tsx
A7: MG-E6 | B7: Column Customization Module | C7: Per-column overrides: header, width, pinning, style, filter config, editor, formatter, row grouping, template chain. | D7: packages/react/widgets/grid-react/src/modules/column-customization
A8: MG-E7 | B8: Column Templates Module | C8: Reusable override bundles with type-default fallback; authored from Formatting Toolbar. | D8: packages/react/widgets/grid-react/src/modules/column-templates
A9: MG-E8 | B9: Calculated Columns Module | C9: Virtual expression-driven columns; transformColumnDefs append, cache invalidation, FormatterPicker integration. | D9: packages/react/widgets/grid-react/src/modules/calculated-columns
A10: MG-E9 | B10: Column Groups Module | C10: Nestable group editor with per-group header styling, openByDefault, marryChildren, tri-state child visibility. | D10: packages/react/widgets/grid-react/src/modules/column-groups
A11: MG-E10 | B11: Conditional Styling Module | C11: IF/THEN rule editor: per-rule expression, scope (cell/row), style, flash, indicator icons, time-limited activations, priority cascade. | D11: packages/react/widgets/grid-react/src/modules/conditional-styling
A12: MG-E11 | B12: Grid State Persistence Module | C12: Capture/replay AG-Grid native state on explicit Save; viewport anchor; quickFilter; reset on new layout. | D12: packages/react/widgets/grid-react/src/modules/grid-state
... A43: MG-E42 | B43: Cross-Framework Parity Invariants | C43: No drift: identical AppConfigRow shape, identical data semantics (getRowId/keyColumn/AppData), identical identity tuple, identical user-facing feature set. | D43: Architecture rule enforced across React + Angular buckets

Sheet Stories
A1: Issue Type | B1: Key | C1: Epic Link | D1: Epic Name | E1: Summary | F1: Description | G1: Acceptance Criteria | H1: Story Points | I1: Priority | J1: Component / Package | K1: Status
A2: Story | B2: MG-1 | C2: MG-E1 | D2: MarketsGrid Public Component & Toolbar Chrome | E2: <MarketsGrid> component with AG-Grid integration | F2: Top-level React widget mounting AgGridReact with platform-aware lifecycle. Accepts gridId, rowData, columnDefs, modules, theme; passes display props through. | G2: 1. Component renders AgGridReact with rowData and columnDefs 2. gridId scopes layout storage 3. modules defaults to DEFAULT_MODULES (9 modules) 4. Theme prop accepts AG-Grid theme objects 5. Unmounts cleanly with no listener / DOM leaks | H2: 5 | I2: High | J2: packages/react/widgets/markets-grid/src/MarketsGrid.tsx | K2: Done
A3: Story | B3: MG-2 | C3: MG-E1 | D3: MarketsGrid Public Component & Toolbar Chrome | E3: MarketsGridHandle imperative ref API | F3: Imperative handle via forwardRef: gridApi, platform, profiles, saveAll(). Host apps drive saves from outside (workspace-save integration). | G3: 1. ref.current.gridApi returns live AG-Grid GridApi after grid-ready 2. ref.current.platform returns the GridPlatform instance 3. ref.current.profiles returns the layout manager hook result 4. ref.current.saveAll() captures grid state and persists active layout (Promise) 5. onReady callback fires once after grid-ready + platform-mount + layout-applied | H3: 3 | I3: High | J3: packages/react/widgets/markets-grid/src/MarketsGrid.tsx | K3: Done
A4: Story | B4: MG-3 | C4: MG-E1 | D4: MarketsGrid Public Component & Toolbar Chrome | E4: Editable caption with pencil affordance | F4: Inline editable caption, visible only when tabsHidden=true; pencil icon reveals input on hover. | G4: 1. tabsHidden=true renders caption above toolbar with hover pencil 2. Click pencil/caption → inline edit input 3. Commit fires onCaptionChange(newCaption) 4. Caption hidden when OpenFin tab strip visible 5. Escapes HTML; uses design-system typography | H4: 2 | I4: Medium | J4: packages/react/widgets/markets-grid/src/MarketsGrid.tsx | K4: Done
A5: Story | B5: MG-4 | C5: MG-E1 | D5: MarketsGrid Public Component & Toolbar Chrome | E5: Save button with dirty glow + flash checkmark | F5: Save button glows when isDirty=true; checkmark for 600 ms after successful save. | G5: 1. Visually emphasized when there are unsaved changes 2. Click triggers saveAll() and toggles saving state 3. On success, checkmark replaces icon for 600 ms then reverts 4. onSavingChange(true|false) fires on start and completion 5. Disabled state during in-flight save | H5: 2 | I5: Medium | J5: packages/react/widgets/markets-grid/src/MarketsGrid.tsx | K5: Done
A6: Story | B6: MG-5 | C6: MG-E1 | D6: MarketsGrid Public Component & Toolbar Chrome | E6: Toolbar visibility flags + adminActions slot | F6: Independent flags + adminActions=[] for host-plugged icon buttons. | G6: 1. showToolbar/showFiltersToolbar/showFormattingToolbar/showSaveButton/showSettingsButton/showProfileSelector each toggle independently 2. adminActions render as icon buttons; each {id, label, icon?, description?, onClick, visible?} 3. Icon preset catalog: database/file-text/list-checks/activity/bar-chart-3/shield-check/users/terminal/eye/wrench/refresh-cw 4. testid admin-action-{id} 5. Async onClick tolerated | H6: 3 | I6: Medium | J6: packages/react/widgets/markets-grid/src/MarketsGrid.tsx | K6: Done
A7: Story | B7: MG-6 | C7: MG-E1 | D7: MarketsGrid Public Component & Toolbar Chrome | E7: Info ⓘ popover with technical identifiers | F7: Popover exposing gridId, instanceId, appId, userId, componentName, componentType, active layout id. | G7: 1. Popover triggered by ⓘ button at toolbar right edge 2. Shows: gridId, instanceId, appId, userId, componentName, registeredIdentity, active layout id + name 3. Per-row copy-to-clipboard 4. Closes on Escape and outside click 5. Designed so support can read off identifiers | H7: 2 | I7: Medium | J7: packages/react/widgets/markets-grid/src/MarketsGrid.tsx | K7: Done
A8: Story | B8: MG-7 | C8: MG-E1 | D8: MarketsGrid Public Component & Toolbar Chrome | E8: headerExtras slot with Alt+Shift+P reveal | F8: ReactNode slot above filters toolbar. Hidden by default; Alt+Shift+P toggles (chosen because Ctrl+Shift+P clashes with browser incognito). | G8: 1. headerExtras content renders above filters toolbar when revealed 2. Alt+Shift+P toggles visibility 3. Slot consumes no vertical space when hidden or unset 4. Visibility state per-session (not persisted) | H8: 2 | I8: Medium | J8: packages/react/widgets/markets-grid/src/MarketsGrid.tsx | K8: Done
A9: Story | B9: MG-8 | C9: MG-E1 | D9: MarketsGrid Public Component & Toolbar Chrome | E9: Grid-level opaque data slot | F9: gridLevelData prop + onGridLevelDataLoad callback for state surviving layout switches. | G9: 1. gridLevelData persisted via storage saveGridLevelData 2. onGridLevelDataLoad fires once after storage load 3. Slot opaque (Record<string, unknown>) 4. Survives layout switches (lives in bundle top-level) 5. Adapters without grid-level support no-op gracefully | H9: 3 | I9: High | J9: packages/react/widgets/markets-grid/src/MarketsGrid.tsx | K9: Done
A10: Story | B10: MG-9 | C10: MG-E1 | D10: MarketsGrid Public Component & Toolbar Chrome | E10: MemoryAdapter dev-mode warning + before-unload prompt | F10: Console.warn once when MemoryAdapter auto-selected in dev. window beforeunload listener while isDirty=true. | G10: 1. Console.warn emitted exactly once per grid in dev when no storage supplied 2. Warning names gridId + recommends real adapter 3. Production build suppresses warning 4. beforeunload listener attached/detached based on isDirty 5. Works in browser and OpenFin views | H10: 2 | I10: Medium | J10: packages/react/widgets/markets-grid/src/MarketsGrid.tsx | K10: Done
A11: Story | B11: MG-10 | C11: MG-E1 | D11: MarketsGrid Public Component & Toolbar Chrome | E11: Strict-mode safe lifecycle | F11: Component remounts cleanly under React StrictMode (double-mount semantics). | G11: 1. StrictMode double-mount produces single platform + single grid 2. EventBus listener count identical after mount/unmount/mount 3. ResourceScope released on unmount even under StrictMode 4. Save flash, popouts, timers cleaned up between strict-mode passes | H11: 3 | I11: Medium | J11: packages/react/widgets/markets-grid/src/MarketsGrid.tsx | K11: Done
A12: Story | B12: MG-11 | C12: MG-E2 | D12: AG-Grid Enterprise Integration | E12: AG-Grid Enterprise v33+ baseline integration | F12: Wrap AgGridReact with all Enterprise modules registered. | G12: 1. ModuleRegistry.registerModules called once at app boot 2. License key configurable per host app 3. Sorting, filtering, grouping, pivoting, pagination operational out of box 4. Side bar + status bar render and respect grid options 5. Excel export + clipboard work in default config | H12: 5 | I12: High | J12: packages/react/widgets/markets-grid (AgGridReact wrapper) | K12: Done
A13: Story | B13: MG-12 | C13: MG-E2 | D13: AG-Grid Enterprise Integration | E13: Frozen rows + columns + virtual scrolling | F13: Pinned-top/bottom rows + pinned-left/right columns through column-customization and general-settings. | G13: 1. Per-column initialPinned (left/right/undefined) honored 2. pinnedTopRowData / pinnedBottomRowData props 3. 50k+ rows scroll smoothly 4. Horizontal virtual scroll under split-pinned layout 5. Pinned columns survive layout save/load | H13: 3 | I13: High | J13: packages/react/widgets/markets-grid (AgGridReact wrapper) | K13: Done
... A187: Story | B187: MG-186 | C187: MG-E42 | D187: Cross-Framework Parity Invariants | E187: Parity invariant: user-facing feature surface tracker | F187: Every React module has Angular counterpart on roadmap. PrimeNG vs shadcn — capability surface identical. | G187: 1. Feature catalog tracked side-by-side 2. Per-module parity status published in docs 3. New React module triggers Angular roadmap entry 4. Users can switch frameworks and find same capabilities 5. PRD review enforces parity at design time | H187: 3 | I187: Medium | J187: Architecture rule enforced across React + Angular buckets | K187: Not Started

Sheet Summary
A1: MarketsGrid + Supporting Infrastructure — Jira Backlog
A2: Source: code-derived inventory (packages/* scan) cross-referenced with marketsgrid-overview.md (2026-05-12)
A4: Metric | B4: Value
A5: Total Epics | B5: =COUNTA(Epics!A2:A43)
A6: Total Stories | B6: =COUNTA(Stories!B2:B187)
A7: Total Story Points | B7: =SUM(Stories!H2:H187)
A8: Average Points / Story | B8: =AVERAGE(Stories!H2:H187)
A9: High Priority Count | B9: =COUNTIF(Stories!I2:I187,"High")
A10: Medium Priority Count | B10: =COUNTIF(Stories!I2:I187,"Medium")
A11: Low Priority Count | B11: =COUNTIF(Stories!I2:I187,"Low")
A13: Points by Epic (with status breakdown)
A14: Epic Key | B14: Epic Name | C14: Stories | D14: Points | E14: Done | F14: In Progress | G14: Not Started
A15: MG-E1 | B15: MarketsGrid Public Component & Toolbar Chrome | C15: =COUNTIF(Stories!C2:C187,"MG-E1") | D15: =SUMIF(Stories!C2:C187,"MG-E1",Stories!H2:H187) | E15: =COUNTIFS(Stories!C2:C187,"MG-E1",Stories!K2:K187,"Done") | F15: =COUNTIFS(Stories!C2:C187,"MG-E1",Stories!K2:K187,"In Progress") | G15: =COUNTIFS(Stories!C2:C187,"MG-E1",Stories!K2:K187,"Not Started")
A16: MG-E2 | B16: AG-Grid Enterprise Integration | C16: =COUNTIF(Stories!C2:C187,"MG-E2") | D16: =SUMIF(Stories!C2:C187,"MG-E2",Stories!H2:H187) | E16: =COUNTIFS(Stories!C2:C187,"MG-E2",Stories!K2:K187,"Done") | F16: =COUNTIFS(Stories!C2:C187,"MG-E2",Stories!K2:K187,"In Progress") | G16: =COUNTIFS(Stories!C2:C187,"MG-E2",Stories!K2:K187,"Not Started")
A17: MG-E3 | B17: Streaming Data Performance | C17: =COUNTIF(Stories!C2:C187,"MG-E3") | D17: =SUMIF(Stories!C2:C187,"MG-E3",Stories!H2:H187) | E17: =COUNTIFS(Stories!C2:C187,"MG-E3",Stories!K2:K187,"Done") | F17: =COUNTIFS(Stories!C2:C187,"MG-E3",Stories!K2:K187,"In Progress") | G17: =COUNTIFS(Stories!C2:C187,"MG-E3",Stories!K2:K187,"Not Started")
A18: MG-E4 | B18: Grid Platform & Module System (Core) | C18: =COUNTIF(Stories!C2:C187,"MG-E4") | D18: =SUMIF(Stories!C2:C187,"MG-E4",Stories!H2:H187) | E18: =COUNTIFS(Stories!C2:C187,"MG-E4",Stories!K2:K187,"Done") | F18: =COUNTIFS(Stories!C2:C187,"MG-E4",Stories!K2:K187,"In Progress") | G18: =COUNTIFS(Stories!C2:C187,"MG-E4",Stories!K2:K187,"Not Started")
A19: MG-E5 | B19: Layout / Profile Management | C19: =COUNTIF(Stories!C2:C187,"MG-E5") | D19: =SUMIF(Stories!C2:C187,"MG-E5",Stories!H2:H187) | E19: =COUNTIFS(Stories!C2:C187,"MG-E5",Stories!K2:K187,"Done") | F19: =COUNTIFS(Stories!C2:C187,"MG-E5",Stories!K2:K187,"In Progress") | G19: =COUNTIFS(Stories!C2:C187,"MG-E5",Stories!K2:K187,"Not Started")
A20: MG-E6 | B20: Column Customization Module | C20: =COUNTIF(Stories!C2:C187,"MG-E6") | D20: =SUMIF(Stories!C2:C187,"MG-E6",Stories!H2:H187) | E20: =COUNTIFS(Stories!C2:C187,"MG-E6",Stories!K2:K187,"Done") | F20: =COUNTIFS(Stories!C2:C187,"MG-E6",Stories!K2:K187,"In Progress") | G20: =COUNTIFS(Stories!C2:C187,"MG-E6",Stories!K2:K187,"Not Started")
A21: MG-E7 | B21: Column Templates Module | C21: =COUNTIF(Stories!C2:C187,"MG-E7") | D21: =SUMIF(Stories!C2:C187,"MG-E7",Stories!H2:H187) | E21: =COUNTIFS(Stories!C2:C187,"MG-E7",Stories!K2:K187,"Done") | F21: =COUNTIFS(Stories!C2:C187,"MG-E7",Stories!K2:K187,"In Progress") | G21: =COUNTIFS(Stories!C2:C187,"MG-E7",Stories!K2:K187,"Not Started")
A22: MG-E8 | B22: Calculated Columns Module | C22: =COUNTIF(Stories!C2:C187,"MG-E8") | D22: =SUMIF(Stories!C2:C187,"MG-E8",Stories!H2:H187) | E22: =COUNTIFS(Stories!C2:C187,"MG-E8",Stories!K2:K187,"Done") | F22: =COUNTIFS(Stories!C2:C187,"MG-E8",Stories!K2:K187,"In Progress") | G22: =COUNTIFS(Stories!C2:C187,"MG-E8",Stories!K2:K187,"Not Started")
A23: MG-E9 | B23: Column Groups Module | C23: =COUNTIF(Stories!C2:C187,"MG-E9") | D23: =SUMIF(Stories!C2:C187,"MG-E9",Stories!H2:H187) | E23: =COUNTIFS(Stories!C2:C187,"MG-E9",Stories!K2:K187,"Done") | F23: =COUNTIFS(Stories!C2:C187,"MG-E9",Stories!K2:K187,"In Progress") | G23: =COUNTIFS(Stories!C2:C187,"MG-E9",Stories!K2:K187,"Not Started")
A24: MG-E10 | B24: Conditional Styling Module | C24: =COUNTIF(Stories!C2:C187,"MG-E10") | D24: =SUMIF(Stories!C2:C187,"MG-E10",Stories!H2:H187) | E24: =COUNTIFS(Stories!C2:C187,"MG-E10",Stories!K2:K187,"Done") | F24: =COUNTIFS(Stories!C2:C187,"MG-E10",Stories!K2:K187,"In Progress") | G24: =COUNTIFS(Stories!C2:C187,"MG-E10",Stories!K2:K187,"Not Started")
A25: MG-E11 | B25: Grid State Persistence Module | C25: =COUNTIF(Stories!C2:C187,"MG-E11") | D25: =SUMIF(Stories!C2:C187,"MG-E11",Stories!H2:H187) | E25: =COUNTIFS(Stories!C2:C187,"MG-E11",Stories!K2:K187,"Done") | F25: =COUNTIFS(Stories!C2:C187,"MG-E11",Stories!K2:K187,"In Progress") | G25: =COUNTIFS(Stories!C2:C187,"MG-E11",Stories!K2:K187,"Not Started")
A26: MG-E12 | B26: Saved Filters Module | C26: =COUNTIF(Stories!C2:C187,"MG-E12") | D26: =SUMIF(Stories!C2:C187,"MG-E12",Stories!H2:H187) | E26: =COUNTIFS(Stories!C2:C187,"MG-E12",Stories!K2:K187,"Done") | F26: =COUNTIFS(Stories!C2:C187,"MG-E12",Stories!K2:K187,"In Progress") | G26: =COUNTIFS(Stories!C2:C187,"MG-E12",Stories!K2:K187,"Not Started")
A27: MG-E13 | B27: Toolbar Visibility Module | C27: =COUNTIF(Stories!C2:C187,"MG-E13") | D27: =SUMIF(Stories!C2:C187,"MG-E13",Stories!H2:H187) | E27: =COUNTIFS(Stories!C2:C187,"MG-E13",Stories!K2:K187,"Done") | F27: =COUNTIFS(Stories!C2:C187,"MG-E13",Stories!K2:K187,"In Progress") | G27: =COUNTIFS(Stories!C2:C187,"MG-E13",Stories!K2:K187,"Not Started")
A28: MG-E14 | B28: Grid Options Settings Panel (general-settings) | C28: =COUNTIF(Stories!C2:C187,"MG-E14") | D28: =SUMIF(Stories!C2:C187,"MG-E14",Stories!H2:H187) | E28: =COUNTIFS(Stories!C2:C187,"MG-E14",Stories!K2:K187,"Done") | F28: =COUNTIFS(Stories!C2:C187,"MG-E14",Stories!K2:K187,"In Progress") | G28: =COUNTIFS(Stories!C2:C187,"MG-E14",Stories!K2:K187,"Not Started")
A29: MG-E15 | B29: Expression Engine & Monaco Editor | C29: =COUNTIF(Stories!C2:C187,"MG-E15") | D29: =SUMIF(Stories!C2:C187,"MG-E15",Stories!H2:H187) | E29: =COUNTIFS(Stories!C2:C187,"MG-E15",Stories!K2:K187,"Done") | F29: =COUNTIFS(Stories!C2:C187,"MG-E15",Stories!K2:K187,"In Progress") | G29: =COUNTIFS(Stories!C2:C187,"MG-E15",Stories!K2:K187,"Not Started")
A30: MG-E16 | B30: Formatter System & FormatterPicker | C30: =COUNTIF(Stories!C2:C187,"MG-E16") | D30: =SUMIF(Stories!C2:C187,"MG-E16",Stories!H2:H187) | E30: =COUNTIFS(Stories!C2:C187,"MG-E16",Stories!K2:K187,"Done") | F30: =COUNTIFS(Stories!C2:C187,"MG-E16",Stories!K2:K187,"In Progress") | G30: =COUNTIFS(Stories!C2:C187,"MG-E16",Stories!K2:K187,"Not Started")
A31: MG-E17 | B31: Settings Drawer & Cockpit UI Primitives | C31: =COUNTIF(Stories!C2:C187,"MG-E17") | D31: =SUMIF(Stories!C2:C187,"MG-E17",Stories!H2:H187) | E31: =COUNTIFS(Stories!C2:C187,"MG-E17",Stories!K2:K187,"Done") | F31: =COUNTIFS(Stories!C2:C187,"MG-E17",Stories!K2:K187,"In Progress") | G31: =COUNTIFS(Stories!C2:C187,"MG-E17",Stories!K2:K187,"Not Started")
A32: MG-E18 | B32: Formatting Toolbar | C32: =COUNTIF(Stories!C2:C187,"MG-E18") | D32: =SUMIF(Stories!C2:C187,"MG-E18",Stories!H2:H187) | E32: =COUNTIFS(Stories!C2:C187,"MG-E18",Stories!K2:K187,"Done") | F32: =COUNTIFS(Stories!C2:C187,"MG-E18",Stories!K2:K187,"In Progress") | G32: =COUNTIFS(Stories!C2:C187,"MG-E18",Stories!K2:K187,"Not Started")
A33: MG-E19 | B33: Filter Pills Bar | C33: =COUNTIF(Stories!C2:C187,"MG-E19") | D33: =SUMIF(Stories!C2:C187,"MG-E19",Stories!H2:H187) | E33: =COUNTIFS(Stories!C2:C187,"MG-E19",Stories!K2:K187,"Done") | F33: =COUNTIFS(Stories!C2:C187,"MG-E19",Stories!K2:K187,"In Progress") | G33: =COUNTIFS(Stories!C2:C187,"MG-E19",Stories!K2:K187,"Not Started")
A34: MG-E20 | B34: Design System Foundation | C34: =COUNTIF(Stories!C2:C187,"MG-E20") | D34: =SUMIF(Stories!C2:C187,"MG-E20",Stories!H2:H187) | E34: =COUNTIFS(Stories!C2:C187,"MG-E20",Stories!K2:K187,"Done") | F34: =COUNTIFS(Stories!C2:C187,"MG-E20",Stories!K2:K187,"In Progress") | G34: =COUNTIFS(Stories!C2:C187,"MG-E20",Stories!K2:K187,"Not Started")
A35: MG-E21 | B35: Storage Adapters | C35: =COUNTIF(Stories!C2:C187,"MG-E21") | D35: =SUMIF(Stories!C2:C187,"MG-E21",Stories!H2:H187) | E35: =COUNTIFS(Stories!C2:C187,"MG-E21",Stories!K2:K187,"Done") | F35: =COUNTIFS(Stories!C2:C187,"MG-E21",Stories!K2:K187,"In Progress") | G35: =COUNTIFS(Stories!C2:C187,"MG-E21",Stories!K2:K187,"Not Started")
A36: MG-E22 | B36: ConfigService Integration | C36: =COUNTIF(Stories!C2:C187,"MG-E22") | D36: =SUMIF(Stories!C2:C187,"MG-E22",Stories!H2:H187) | E36: =COUNTIFS(Stories!C2:C187,"MG-E22",Stories!K2:K187,"Done") | F36: =COUNTIFS(Stories!C2:C187,"MG-E22",Stories!K2:K187,"In Progress") | G36: =COUNTIFS(Stories!C2:C187,"MG-E22",Stories!K2:K187,"Not Started")
A37: MG-E23 | B37: Popout / OpenFin Window Support | C37: =COUNTIF(Stories!C2:C187,"MG-E23") | D37: =SUMIF(Stories!C2:C187,"MG-E23",Stories!H2:H187) | E37: =COUNTIFS(Stories!C2:C187,"MG-E23",Stories!K2:K187,"Done") | F37: =COUNTIFS(Stories!C2:C187,"MG-E23",Stories!K2:K187,"In Progress") | G37: =COUNTIFS(Stories!C2:C187,"MG-E23",Stories!K2:K187,"Not Started")
A38: MG-E24 | B38: Expression Security Policy | C38: =COUNTIF(Stories!C2:C187,"MG-E24") | D38: =SUMIF(Stories!C2:C187,"MG-E24",Stories!H2:H187) | E38: =COUNTIFS(Stories!C2:C187,"MG-E24",Stories!K2:K187,"Done") | F38: =COUNTIFS(Stories!C2:C187,"MG-E24",Stories!K2:K187,"In Progress") | G38: =COUNTIFS(Stories!C2:C187,"MG-E24",Stories!K2:K187,"Not Started")
A39: MG-E25 | B39: Admin Actions | C39: =COUNTIF(Stories!C2:C187,"MG-E25") | D39: =SUMIF(Stories!C2:C187,"MG-E25",Stories!H2:H187) | E39: =COUNTIFS(Stories!C2:C187,"MG-E25",Stories!K2:K187,"Done") | F39: =COUNTIFS(Stories!C2:C187,"MG-E25",Stories!K2:K187,"In Progress") | G39: =COUNTIFS(Stories!C2:C187,"MG-E25",Stories!K2:K187,"Not Started")
A40: MG-E26 | B40: App-Data Binding | C40: =COUNTIF(Stories!C2:C187,"MG-E26") | D40: =SUMIF(Stories!C2:C187,"MG-E26",Stories!H2:H187) | E40: =COUNTIFS(Stories!C2:C187,"MG-E26",Stories!K2:K187,"Done") | F40: =COUNTIFS(Stories!C2:C187,"MG-E26",Stories!K2:K187,"In Progress") | G40: =COUNTIFS(Stories!C2:C187,"MG-E26",Stories!K2:K187,"Not Started")
A41: MG-E27 | B41: MarketsGridContainer (Data Provider Layer) | C41: =COUNTIF(Stories!C2:C187,"MG-E27") | D41: =SUMIF(Stories!C2:C187,"MG-E27",Stories!H2:H187) | E41: =COUNTIFS(Stories!C2:C187,"MG-E27",Stories!K2:K187,"Done") | F41: =COUNTIFS(Stories!C2:C187,"MG-E27",Stories!K2:K187,"In Progress") | G41: =COUNTIFS(Stories!C2:C187,"MG-E27",Stories!K2:K187,"Not Started")
A42: MG-E28 | B42: Data Services Runtime | C42: =COUNTIF(Stories!C2:C187,"MG-E28") | D42: =SUMIF(Stories!C2:C187,"MG-E28",Stories!H2:H187) | E42: =COUNTIFS(Stories!C2:C187,"MG-E28",Stories!K2:K187,"Done") | F42: =COUNTIFS(Stories!C2:C187,"MG-E28",Stories!K2:K187,"In Progress") | G42: =COUNTIFS(Stories!C2:C187,"MG-E28",Stories!K2:K187,"Not Started")
...
